Workbook

Sheet Anleitung
B1: Entscheidungsbaum Zählerschrank – Praxistest (Pilot: Westnetz)
B2: Zweck: Prüfen, ob ein einfacher Regelbaum bei deinen realen Schränken zur gleichen Entscheidung kommt wie du. Erst wenn das klappt, lohnt sich Software.
B4: So gehst du vor
B5: 1. Blatt „Fälle“: pro realem Zählerschrank eine Zeile. Nur die gelben Zellen ausfüllen, fast alles per Auswahlliste.
B6: 2. In Spalte „DEINE tatsächliche Entscheidung“ einträgst, was du wirklich gemacht hast bzw. was der Netzbetreiber verlangt hat.
B7: 3. Die grauen Spalten rechnen selbst: welche Regeln greifen, Ampel des Tools, Treffer ja/nein.
B8: 4. Stimmt ein Fall nicht: Im Blatt „Regeln“ die Stufe anpassen oder die fehlende Regel in „Deine Notiz“ beschreiben – das ist der eigentliche Erkenntnisgewinn.
B9: 5. Blatt „Auswertung“: Trefferquote, Abweichungsmatrix, Häufigkeit je Regel und die Go/No-Go-Kriterien (Interviews und Warteliste dort eintragen).
B11: Farben
B12: Gelbe Zelle, blaue Schrift = Eingabe von dir. Graue Zelle = Formel, nicht überschreiben. Grüne Schrift = Verweis auf ein anderes Blatt.
B14: Begriffe
B15: SteuVE = steuerbare Verbrauchseinrichtung nach §14a EnWG (Wallbox, Wärmepumpe, Klimagerät, Speicher) ab 4,2 kW. PV ist KEINE SteuVE, sie läuft über EEG / Solarspitzengesetz.
... B23: Die Beispielzeile in „Fälle“ wird in der Auswertung nicht mitgezählt.

Sheet Fälle
A1: Fälle – Praxistest Entscheidungsbaum Zählerschrank
A2: Eingaben (gelb) – deine realen Schränke | AG2: Berechnet – nicht überschreiben | AI2: Zählerplatz nicht weiterverwendbar | AJ2: Zählerplatzverdrahtung unzureichend | AK2: Sicherheitsmängel | AL2: Kein Raum für Zusatzanwendungen | AM2: Modul 2 ohne Zählerplatz | AN2: Keine Trennstelle hinter dem Zähler | AO2: Kein SPD Typ 1 | AP2: Wechselstromanschluss | AQ2: Erdung unklar | AR2: Netzform TN-C / unklar | AS2: Leistungsbilanz knapp | AT2: Wallbox > 12 kVA | AU2: Bauart unbekannt | AV2: DIN-43870-Schrank nur mit Anpassung | AW2: Keine RJ45-Buchse „CLS“ | AX2: Relaissteuerung ohne Steuersignal-Klemmleiste | AY2: Keine Datenleitung zur SteuVE | AZ2: Direktmessung überschritten | BA2: Verdrahtung 10 mm² zu schwach | BB2: PV ≥ 25 kWp ohne FRE | BC2: PV mit Smart-Meter-Steuerung | BD2: Zählerauftrag durch Westnetz | BE2: 3-Punkt-Zähler bei Relaissteuerung | BF2: PV: 60 %-Begrenzung bis SMGW | BG2: Speicher-Betriebsweise klären | BH2: Relaissteuerung nur bis 2028
A3: Fall-Nr | B3: Datum | C3: PLZ / Ort | D3: Netzbetreiber | E3: Wallbox | F3: Wärme- pumpe | G3: Klima- gerät | H3: Speicher | I3: PV | J3: Größte SteuVE (kW; WP inkl. Heizstab und Klima je Art summiert) | K3: §14a-Modul geplant | L3: Zählerplatz-Bauart (BDEW Anhang G) | M3: Zähler- befestigung | N3: Freie Zähler- plätze | O3: APZ / RfZ vorhanden | P3: Trennstelle hinter Zähler (HS/RCD im AAR) | Q3: SPD Typ 1 vorhanden | R3: Anschluss | S3: Netzform | T3: HA-Sicherung (A) | U3: Erdung vorhanden | V3: Zustand / Berührungs-schutz ok | W3: Steuerung geplant über | X3: RJ45-Buchse „CLS“ vorhanden | Y3: 6-polige Steuersignal-Klemmleiste vorhanden | Z3: Datenleitung Cat.5+ SteuVE → Zählerplatz | AA3: Zählerplatz-verdrahtung | AB3: Summe Dauerbetrieb nach Umbau (kW) | AC3: PV-Leistung (kWp) | AD3: Freies Steuer-gerätefeld | AE3: DEINE tatsächliche Entscheidung | AF3: Bemerkung | AG3: Anz. Vorhaben | AH3: SteuVE ≥ 4,2 kW | AI3: R01 | AJ3: R02 | AK3: R03 | AL3: R04 | AM3: R05 | AN3: R06 | AO3: R07 | AP3: R08 | AQ3: R09 | AR3: R10 | AS3: R11 | AT3: R12 | AU3: R13 | AV3: R14 | AW3: R15 | AX3: R16 | AY3: R17 | AZ3: R18 | BA3: R19 | BB3: R20 | BC3: R21 | BD3: R22 | BE3: R23 | BF3: R24 | BG3: R25 | BH3: R26 | BI3: Ergebnis Tool | BJ3: Ausgelöste Regeln | BK3: Treffer? | BL3: Messkonzept Westnetz (Vorschlag)
A4: Beispiel | B4: 46280 | C4: 12345 Musterstadt | D4: Westnetz | E4: Ja | F4: Nein | G4: Nein | H4: Nein | I4: Nein | J4: 11 | K4: Modul 1 | L4: DIN 43870 Zählerschrank, NH-Sicherung im NAR | M4: 3-Punkt | N4: 0 | O4: Nein | P4: Nein | Q4: Nein | R4: 3-phasig | S4: TN-C-S | T4: 63 | U4: Ja | V4: Ja | W4: Digital (RJ45 / EEBUS) | X4: Nein | Y4: Nein | Z4: Ja | AA4: 10 mm² flexibel | AB4: 11 | AD4: Nein | AE4: Nachrüsten | AF4: Beispielzeile – wird in der Auswertung nicht gezählt. Überschreiben oder stehen lassen. | AG4: =IF($A4="","",COUNTIF($E4:$I4,"Ja")) -> 1 | AH4: =IF($A4="","",IF(AND(COUNTIF($E4:$H4,"Ja")>0,N($J4)>=4.2),"Ja","Nein")) -> Ja | AI4: =IF($A4="","",IF(AND(OR($L4="DIN 43853 Zählertafel ohne Schutzklasse II",$L4="DIN 43853 Norm-Zählertafel (Schutzklasse II)",$L4="DIN 43870 Norm-Zählertafel mit Vorsicherung"),$AG4>0),Regeln!$E$5,"")) | AJ4: =IF($A4="","",IF(AND(OR($L4="DIN 43870 Zählerschrank, Trennvorrichtung im AAR",$L4="DIN 43870 Zählerschrank, NH-Sicherung im NAR"),OR($AA4="unter 10 mm² oder starr",$AA4="Unbekannt",$AA4=""),$AG4>0),Regeln!$E$6,"")) | AK4: =IF($A4="","",IF(AND($V4="Nein",$AG4>0),Regeln!$E$7,"")) | AL4: =IF($A4="","",IF(AND(OR($AH4="Ja",$I4="Ja"),$O4="Nein"),Regeln!$E$8,"")) -> 1 | AM4: =IF($A4="","",IF(AND($K4="Modul 2",N($N4)<1),Regeln!$E$9,"")) | AN4: =IF($A4="","",IF(AND($P4="Nein",$AG4>0,OR(ISNUMBER(SEARCH("westnetz",$D4)),$M4="3-Punkt")),Regeln!$E$10,"")) -> 1 | AO4: =IF($A4="","",IF(AND($Q4="Nein",$AG4>0),Regeln!$E$11,"")) -> 1 | AP4: =IF($A4="","",IF(AND($R4="1-phasig",OR(N($J4)>4.6,$I4="Ja")),Regeln!$E$12,"")) | AQ4: =IF($A4="","",IF(OR($U4="Nein",$U4="Unbekannt"),Regeln!$E$13,"")) | AR4: =IF($A4="","",IF(OR($S4="TN-C",$S4="Unbekannt"),Regeln!$E$14,"")) | AS4: =IF($A4="","",IF(AND(N($T4)>0,N($T4)<50,$AG4>=2),Regeln!$E$15,"")) | AT4: =IF($A4="","",IF(AND($E4="Ja",N($J4)>12),Regeln!$E$16,"")) | AU4: =IF($A4="","",IF($L4="Unbekannt",Regeln!$E$17,"")) | AV4: =IF($A4="","",IF(AND(OR($L4="DIN 43870 Zählerschrank, Trennvorrichtung im AAR",$L4="DIN 43870 Zählerschrank, NH-Sicherung im NAR"),$AG4>0),Regeln!$E$18,"")) -> 1 | AW4: =IF($A4="","",IF(AND(ISNUMBER(SEARCH("westnetz",$D4)),OR($AH4="Ja",$I4="Ja"),$X4="Nein"),Regeln!$E$19,"")) -> 1 | AX4: =IF($A4="","",IF(AND(ISNUMBER(SEARCH("westnetz",$D4)),OR($W4="Relais (potentialfrei)",$W4="Digital + Relais",AND($I4="Ja",N($AC4)>=25)),$Y4="Nein"),Regeln!$E$20,"")) | AY4: =IF($A4="","",IF(AND(ISNUMBER(SEARCH("westnetz",$D4)),OR($W4="Digital (RJ45 / EEBUS)",$W4="Digital + Relais"),$Z4="Nein"),Regeln!$E$21,"")) | AZ4: =IF($A4="","",IF(AND(ISNUMBER(SEARCH("westnetz",$D4)),N($AB4)>30),Regeln!$E$22,"")) | BA4: =IF($A4="","",IF(AND($AA4="10 mm² flexibel",N($AB4)*1000/(SQRT(3)*400)>32),Regeln!$E$23,"")) | BB4: =IF($A4="","",IF(AND(ISNUMBER(SEARCH("westnetz",$D4)),$I4="Ja",N($AC4)>=25),Regeln!$E$24,"")) | BC4: =IF($A4="","",IF(AND(ISNUMBER(SEARCH("westnetz",$D4)),$I4="Ja",OR($AH4="Ja",N($AC4)>7)),Regeln!$E$25,"")) | BD4: =IF($A4="","",IF(AND(ISNUMBER(SEARCH("westnetz",$D4)),$AH4="Ja"),Regeln!$E$26,"")) -> 0 | BE4: =IF($A4="","",IF(AND(ISNUMBER(SEARCH("westnetz",$D4)),OR($W4="Relais (potentialfrei)",$W4="Digital + Relais"),$M4="3-Punkt",$AD4="Nein"),Regeln!$E$27,"")) | BF4: =IF($A4="","",IF(AND(ISNUMBER(SEARCH("westnetz",$D4)),$I4="Ja"),Regeln!$E$28,"")) | BG4: =IF($A4="","",IF(AND(ISNUMBER(SEARCH("westnetz",$D4)),$H4="Ja"),Regeln!$E$29,"")) | BH4: =IF($A4="","",IF(AND(ISNUMBER(SEARCH("westnetz",$D4)),OR($W4="Relais (potentialfrei)",$W4="Digital + Relais")),Regeln!$E$30,"")) | BI4: =IF($A4="","",IF($AG4=0,"Kein Vorhaben",CHOOSE(MAX(AI4:BH4)+1,"Weiterverwendbar","Nachrüsten","Austausch"))) -> Nachrüsten | BJ4: =IF($A4="","",_xlfn.TEXTJOIN(", ",TRUE(),IF(AI4<>"",AI$3,""),IF(AJ4<>"",AJ$3,""),IF(AK4<>"",AK$3,""),IF(AL4<>"",AL$3,""),IF(AM4<>"",AM$3,""),IF(AN4<>"",AN$3,""),IF(AO4<>"",AO$3,""),IF(AP4<>"",AP$3,""),IF(AQ4<>"",AQ$3,""),IF(AR4<>"",AR$3,""),IF(AS4<>"",AS$3,""),IF(AT4<>"",AT$3,""),IF(AU4<>"",AU$3,""),IF(AV4<>"",AV$3,""),IF(AW4<>"",AW$3,""),IF(AX4<>"",AX$3,""),IF(AY4<>"",AY$3,""),IF(AZ4<>"",AZ$3,""),IF(BA4<>"",BA$3,""),IF(BB4<>"",BB$3,""),IF(BC4<>"",BC$3,""),IF(BD4<>"",BD$3,""),IF(BE4<>"",BE$3,""),IF(BF4<>"",BF$3,""),IF(BG4<>"",BG$3,""),IF(BH4<>"",BH$3,""))) -> R04, R06, R07, R14, R15, R22 | BK4: =IF(OR($A4="",$AE4=""),"",IF(BI4=$AE4,"Ja","Nein")) -> Ja | BL4: =IF($A4="","",IF(NOT(ISNUMBER(SEARCH("westnetz",$D4))),"–",IF($I4="Ja",IF($K4="Modul 2","MK 8 (Kaskade: Z1 SteuVE, Z2 Haushalt)","MK 2 (Überschuss)"),IF($K4="Modul 2","MK 0 + eigener Zählpunkt SteuVE","MK 0")))) -> MK 0
AG5: =IF($A5="","",COUNTIF($E5:$I5,"Ja")) | AH5: =IF($A5="","",IF(AND(COUNTIF($E5:$H5,"Ja")>0,N($J5)>=4.2),"Ja","Nein")) | AI5: =IF($A5="","",IF(AND(OR($L5="DIN 43853 Zählertafel ohne Schutzklasse II",$L5="DIN 43853 Norm-Zählertafel (Schutzklasse II)",$L5="DIN 43870 Norm-Zählertafel mit Vorsicherung"),$AG5>0),Regeln!$E$5,"")) | AJ5: =IF($A5="","",IF(AND(OR($L5="DIN 43870 Zählerschrank, Trennvorrichtung im AAR",$L5="DIN 43870 Zählerschrank, NH-Sicherung im NAR"),OR($AA5="unter 10 mm² oder starr",$AA5="Unbekannt",$AA5=""),$AG5>0),Regeln!$E$6,"")) | AK5: =IF($A5="","",IF(AND($V5="Nein",$AG5>0),Regeln!$E$7,"")) | AL5: =IF($A5="","",IF(AND(OR($AH5="Ja",$I5="Ja"),$O5="Nein"),Regeln!$E$8,"")) | AM5: =IF($A5="","",IF(AND($K5="Modul 2",N($N5)<1),Regeln!$E$9,"")) | AN5: =IF($A5="","",IF(AND($P5="Nein",$AG5>0,OR(ISNUMBER(SEARCH("westnetz",$D5)),$M5="3-Punkt")),Regeln!$E$10,"")) | AO5: =IF($A5="","",IF(AND($Q5="Nein",$AG5>0),Regeln!$E$11,"")) | AP5: =IF($A5="","",IF(AND($R5="1-phasig",OR(N($J5)>4.6,$I5="Ja")),Regeln!$E$12,"")) | AQ5: =IF($A5="","",IF(OR($U5="Nein",$U5="Unbekannt"),Regeln!$E$13,"")) | AR5: =IF($A5="","",IF(OR($S5="TN-C",$S5="Unbekannt"),Regeln!$E$14,"")) | AS5: =IF($A5="","",IF(AND(N($T5)>0,N($T5)<50,$AG5>=2),Regeln!$E$15,"")) | AT5: =IF($A5="","",IF(AND($E5="Ja",N($J5)>12),Regeln!$E$16,"")) | AU5: =IF($A5="","",IF($L5="Unbekannt",Regeln!$E$17,"")) | AV5: =IF($A5="","",IF(AND(OR($L5="DIN 43870 Zählerschrank, Trennvorrichtung im AAR",$L5="DIN 43870 Zählerschrank, NH-Sicherung im NAR"),$AG5>0),Regeln!$E$18,"")) | AW5: =IF($A5="","",IF(AND(ISNUMBER(SEARCH("westnetz",$D5)),OR($AH5="Ja",$I5="Ja"),$X5="Nein"),Regeln!$E$19,"")) | AX5: =IF($A5="","",IF(AND(ISNUMBER(SEARCH("westnetz",$D5)),OR($W5="Relais (potentialfrei)",$W5="Digital + Relais",AND($I5="Ja",N($AC5)>=25)),$Y5="Nein"),Regeln!$E$20,"")) | AY5: =IF($A5="","",IF(AND(ISNUMBER(SEARCH("westnetz",$D5)),OR($W5="Digital (RJ45 / EEBUS)",$W5="Digital + Relais"),$Z5="Nein"),Regeln!$E$21,"")) | AZ5: =IF($A5="","",IF(AND(ISNUMBER(SEARCH("westnetz",$D5)),N($AB5)>30),Regeln!$E$22,"")) | BA5: =IF($A5="","",IF(AND($AA5="10 mm² flexibel",N($AB5)*1000/(SQRT(3)*400)>32),Regeln!$E$23,"")) | BB5: =IF($A5="","",IF(AND(ISNUMBER(SEARCH("westnetz",$D5)),$I5="Ja",N($AC5)>=25),Regeln!$E$24,"")) | BC5: =IF($A5="","",IF(AND(ISNUMBER(SEARCH("westnetz",$D5)),$I5="Ja",OR($AH5="Ja",N($AC5)>7)),Regeln!$E$25,"")) | BD5: =IF($A5="","",IF(AND(ISNUMBER(SEARCH("westnetz",$D5)),$AH5="Ja"),Regeln!$E$26,"")) | BE5: =IF($A5="","",IF(AND(ISNUMBER(SEARCH("westnetz",$D5)),OR($W5="Relais (potentialfrei)",$W5="Digital + Relais"),$M5="3-Punkt",$AD5="Nein"),Regeln!$E$27,"")) | BF5: =IF($A5="","",IF(AND(ISNUMBER(SEARCH("westnetz",$D5)),$I5="Ja"),Regeln!$E$28,"")) | BG5: =IF($A5="","",IF(AND(ISNUMBER(SEARCH("westnetz",$D5)),$H5="Ja"),Regeln!$E$29,"")) | BH5: =IF($A5="","",IF(AND(ISNUMBER(SEARCH("westnetz",$D5)),OR($W5="Relais (potentialfrei)",$W5="Digital + Relais")),Regeln!$E$30,"")) | BI5: =IF($A5="","",IF($AG5=0,"Kein Vorhaben",CHOOSE(MAX(AI5:BH5)+1,"Weiterverwendbar","Nachrüsten","Austausch"))) | BJ5: =IF($A5="","",_xlfn.TEXTJOIN(", ",TRUE(),IF(AI5<>"",AI$3,""),IF(AJ5<>"",AJ$3,""),IF(AK5<>"",AK$3,""),IF(AL5<>"",AL$3,""),IF(AM5<>"",AM$3,""),IF(AN5<>"",AN$3,""),IF(AO5<>"",AO$3,""),IF(AP5<>"",AP$3,""),IF(AQ5<>"",AQ$3,""),IF(AR5<>"",AR$3,""),IF(AS5<>"",AS$3,""),IF(AT5<>"",AT$3,""),IF(AU5<>"",AU$3,""),IF(AV5<>"",AV$3,""),IF(AW5<>"",AW$3,""),IF(AX5<>"",AX$3,""),IF(AY5<>"",AY$3,""),IF(AZ5<>"",AZ$3,""),IF(BA5<>"",BA$3,""),IF(BB5<>"",BB$3,""),IF(BC5<>"",BC$3,""),IF(BD5<>"",BD$3,""),IF(BE5<>"",BE$3,""),IF(BF5<>"",BF$3,""),IF(BG5<>"",BG$3,""),IF(BH5<>"",BH$3,""))) | BK5: =IF(OR($A5="",$AE5=""),"",IF(BI5=$AE5,"Ja","Nein")) | BL5: =IF($A5="","",IF(NOT(ISNUMBER(SEARCH("westnetz",$D5))),"–",IF($I5="Ja",IF($K5="Modul 2","MK 8 (Kaskade: Z1 SteuVE, Z2 Haushalt)","MK 2 (Überschuss)"),IF($K5="Modul 2","MK 0 + eigener Zählpunkt SteuVE","MK 0"))))
AG6: =IF($A6="","",COUNTIF($E6:$I6,"Ja")) | AH6: =IF($A6="","",IF(AND(COUNTIF($E6:$H6,"Ja")>0,N($J6)>=4.2),"Ja","Nein")) | AI6: =IF($A6="","",IF(AND(OR($L6="DIN 43853 Zählertafel ohne Schutzklasse II",$L6="DIN 43853 Norm-Zählertafel (Schutzklasse II)",$L6="DIN 43870 Norm-Zählertafel mit Vorsicherung"),$AG6>0),Regeln!$E$5,"")) | AJ6: =IF($A6="","",IF(AND(OR($L6="DIN 43870 Zählerschrank, Trennvorrichtung im AAR",$L6="DIN 43870 Zählerschrank, NH-Sicherung im NAR"),OR($AA6="unter 10 mm² oder starr",$AA6="Unbekannt",$AA6=""),$AG6>0),Regeln!$E$6,"")) | AK6: =IF($A6="","",IF(AND($V6="Nein",$AG6>0),Regeln!$E$7,"")) | AL6: =IF($A6="","",IF(AND(OR($AH6="Ja",$I6="Ja"),$O6="Nein"),Regeln!$E$8,"")) | AM6: =IF($A6="","",IF(AND($K6="Modul 2",N($N6)<1),Regeln!$E$9,"")) | AN6: =IF($A6="","",IF(AND($P6="Nein",$AG6>0,OR(ISNUMBER(SEARCH("westnetz",$D6)),$M6="3-Punkt")),Regeln!$E$10,"")) | AO6: =IF($A6="","",IF(AND($Q6="Nein",$AG6>0),Regeln!$E$11,"")) | AP6: =IF($A6="","",IF(AND($R6="1-phasig",OR(N($J6)>4.6,$I6="Ja")),Regeln!$E$12,"")) | AQ6: =IF($A6="","",IF(OR($U6="Nein",$U6="Unbekannt"),Regeln!$E$13,"")) | AR6: =IF($A6="","",IF(OR($S6="TN-C",$S6="Unbekannt"),Regeln!$E$14,"")) | AS6: =IF($A6="","",IF(AND(N($T6)>0,N($T6)<50,$AG6>=2),Regeln!$E$15,"")) | AT6: =IF($A6="","",IF(AND($E6="Ja",N($J6)>12),Regeln!$E$16,"")) | AU6: =IF($A6="","",IF($L6="Unbekannt",Regeln!$E$17,"")) | AV6: =IF($A6="","",IF(AND(OR($L6="DIN 43870 Zählerschrank, Trennvorrichtung im AAR",$L6="DIN 43870 Zählerschrank, NH-Sicherung im NAR"),$AG6>0),Regeln!$E$18,"")) | AW6: =IF($A6="","",IF(AND(ISNUMBER(SEARCH("westnetz",$D6)),OR($AH6="Ja",$I6="Ja"),$X6="Nein"),Regeln!$E$19,"")) | AX6: =IF($A6="","",IF(AND(ISNUMBER(SEARCH("westnetz",$D6)),OR($W6="Relais (potentialfrei)",$W6="Digital + Relais",AND($I6="Ja",N($AC6)>=25)),$Y6="Nein"),Regeln!$E$20,"")) | AY6: =IF($A6="","",IF(AND(ISNUMBER(SEARCH("westnetz",$D6)),OR($W6="Digital (RJ45 / EEBUS)",$W6="Digital + Relais"),$Z6="Nein"),Regeln!$E$21,"")) | AZ6: =IF($A6="","",IF(AND(ISNUMBER(SEARCH("westnetz",$D6)),N($AB6)>30),Regeln!$E$22,"")) | BA6: =IF($A6="","",IF(AND($AA6="10 mm² flexibel",N($AB6)*1000/(SQRT(3)*400)>32),Regeln!$E$23,"")) | BB6: =IF($A6="","",IF(AND(ISNUMBER(SEARCH("westnetz",$D6)),$I6="Ja",N($AC6)>=25),Regeln!$E$24,"")) | BC6: =IF($A6="","",IF(AND(ISNUMBER(SEARCH("westnetz",$D6)),$I6="Ja",OR($AH6="Ja",N($AC6)>7)),Regeln!$E$25,"")) | BD6: =IF($A6="","",IF(AND(ISNUMBER(SEARCH("westnetz",$D6)),$AH6="Ja"),Regeln!$E$26,"")) | BE6: =IF($A6="","",IF(AND(ISNUMBER(SEARCH("westnetz",$D6)),OR($W6="Relais (potentialfrei)",$W6="Digital + Relais"),$M6="3-Punkt",$AD6="Nein"),Regeln!$E$27,"")) | BF6: =IF($A6="","",IF(AND(ISNUMBER(SEARCH("westnetz",$D6)),$I6="Ja"),Regeln!$E$28,"")) | BG6: =IF($A6="","",IF(AND(ISNUMBER(SEARCH("westnetz",$D6)),$H6="Ja"),Regeln!$E$29,"")) | BH6: =IF($A6="","",IF(AND(ISNUMBER(SEARCH("westnetz",$D6)),OR($W6="Relais (potentialfrei)",$W6="Digital + Relais")),Regeln!$E$30,"")) | BI6: =IF($A6="","",IF($AG6=0,"Kein Vorhaben",CHOOSE(MAX(AI6:BH6)+1,"Weiterverwendbar","Nachrüsten","Austausch"))) | BJ6: =IF($A6="","",_xlfn.TEXTJOIN(", ",TRUE(),IF(AI6<>"",AI$3,""),IF(AJ6<>"",AJ$3,""),IF(AK6<>"",AK$3,""),IF(AL6<>"",AL$3,""),IF(AM6<>"",AM$3,""),IF(AN6<>"",AN$3,""),IF(AO6<>"",AO$3,""),IF(AP6<>"",AP$3,""),IF(AQ6<>"",AQ$3,""),IF(AR6<>"",AR$3,""),IF(AS6<>"",AS$3,""),IF(AT6<>"",AT$3,""),IF(AU6<>"",AU$3,""),IF(AV6<>"",AV$3,""),IF(AW6<>"",AW$3,""),IF(AX6<>"",AX$3,""),IF(AY6<>"",AY$3,""),IF(AZ6<>"",AZ$3,""),IF(BA6<>"",BA$3,""),IF(BB6<>"",BB$3,""),IF(BC6<>"",BC$3,""),IF(BD6<>"",BD$3,""),IF(BE6<>"",BE$3,""),IF(BF6<>"",BF$3,""),IF(BG6<>"",BG$3,""),IF(BH6<>"",BH$3,""))) | BK6: =IF(OR($A6="",$AE6=""),"",IF(BI6=$AE6,"Ja","Nein")) | BL6: =IF($A6="","",IF(NOT(ISNUMBER(SEARCH("westnetz",$D6))),"–",IF($I6="Ja",IF($K6="Modul 2","MK 8 (Kaskade: Z1 SteuVE, Z2 Haushalt)","MK 2 (Überschuss)"),IF($K6="Modul 2","MK 0 + eigener Zählpunkt SteuVE","MK 0"))))
AG7: =IF($A7="","",COUNTIF($E7:$I7,"Ja")) | AH7: =IF($A7="","",IF(AND(COUNTIF($E7:$H7,"Ja")>0,N($J7)>=4.2),"Ja","Nein")) | AI7: =IF($A7="","",IF(AND(OR($L7="DIN 43853 Zählertafel ohne Schutzklasse II",$L7="DIN 43853 Norm-Zählertafel (Schutzklasse II)",$L7="DIN 43870 Norm-Zählertafel mit Vorsicherung"),$AG7>0),Regeln!$E$5,"")) | AJ7: =IF($A7="","",IF(AND(OR($L7="DIN 43870 Zählerschrank, Trennvorrichtung im AAR",$L7="DIN 43870 Zählerschrank, NH-Sicherung im NAR"),OR($AA7="unter 10 mm² oder starr",$AA7="Unbekannt",$AA7=""),$AG7>0),Regeln!$E$6,"")) | AK7: =IF($A7="","",IF(AND($V7="Nein",$AG7>0),Regeln!$E$7,"")) | AL7: =IF($A7="","",IF(AND(OR($AH7="Ja",$I7="Ja"),$O7="Nein"),Regeln!$E$8,"")) | AM7: =IF($A7="","",IF(AND($K7="Modul 2",N($N7)<1),Regeln!$E$9,"")) | AN7: =IF($A7="","",IF(AND($P7="Nein",$AG7>0,OR(ISNUMBER(SEARCH("westnetz",$D7)),$M7="3-Punkt")),Regeln!$E$10,"")) | AO7: =IF($A7="","",IF(AND($Q7="Nein",$AG7>0),Regeln!$E$11,"")) | AP7: =IF($A7="","",IF(AND($R7="1-phasig",OR(N($J7)>4.6,$I7="Ja")),Regeln!$E$12,"")) | AQ7: =IF($A7="","",IF(OR($U7="Nein",$U7="Unbekannt"),Regeln!$E$13,"")) | AR7: =IF($A7="","",IF(OR($S7="TN-C",$S7="Unbekannt"),Regeln!$E$14,"")) | AS7: =IF($A7="","",IF(AND(N($T7)>0,N($T7)<50,$AG7>=2),Regeln!$E$15,"")) | AT7: =IF($A7="","",IF(AND($E7="Ja",N($J7)>12),Regeln!$E$16,"")) | AU7: =IF($A7="","",IF($L7="Unbekannt",Regeln!$E$17,"")) | AV7: =IF($A7="","",IF(AND(OR($L7="DIN 43870 Zählerschrank, Trennvorrichtung im AAR",$L7="DIN 43870 Zählerschrank, NH-Sicherung im NAR"),$AG7>0),Regeln!$E$18,"")) | AW7: =IF($A7="","",IF(AND(ISNUMBER(SEARCH("westnetz",$D7)),OR($AH7="Ja",$I7="Ja"),$X7="Nein"),Regeln!$E$19,"")) | AX7: =IF($A7="","",IF(AND(ISNUMBER(SEARCH("westnetz",$D7)),OR($W7="Relais (potentialfrei)",$W7="Digital + Relais",AND($I7="Ja",N($AC7)>=25)),$Y7="Nein"),Regeln!$E$20,"")) | AY7: =IF($A7="","",IF(AND(ISNUMBER(SEARCH("westnetz",$D7)),OR($W7="Digital (RJ45 / EEBUS)",$W7="Digital + Relais"),$Z7="Nein"),Regeln!$E$21,"")) | AZ7: =IF($A7="","",IF(AND(ISNUMBER(SEARCH("westnetz",$D7)),N($AB7)>30),Regeln!$E$22,"")) | BA7: =IF($A7="","",IF(AND($AA7="10 mm² flexibel",N($AB7)*1000/(SQRT(3)*400)>32),Regeln!$E$23,"")) | BB7: =IF($A7="","",IF(AND(ISNUMBER(SEARCH("westnetz",$D7)),$I7="Ja",N($AC7)>=25),Regeln!$E$24,"")) | BC7: =IF($A7="","",IF(AND(ISNUMBER(SEARCH("westnetz",$D7)),$I7="Ja",OR($AH7="Ja",N($AC7)>7)),Regeln!$E$25,"")) | BD7: =IF($A7="","",IF(AND(ISNUMBER(SEARCH("westnetz",$D7)),$AH7="Ja"),Regeln!$E$26,"")) | BE7: =IF($A7="","",IF(AND(ISNUMBER(SEARCH("westnetz",$D7)),OR($W7="Relais (potentialfrei)",$W7="Digital + Relais"),$M7="3-Punkt",$AD7="Nein"),Regeln!$E$27,"")) | BF7: =IF($A7="","",IF(AND(ISNUMBER(SEARCH("westnetz",$D7)),$I7="Ja"),Regeln!$E$28,"")) | BG7: =IF($A7="","",IF(AND(ISNUMBER(SEARCH("westnetz",$D7)),$H7="Ja"),Regeln!$E$29,"")) | BH7: =IF($A7="","",IF(AND(ISNUMBER(SEARCH("westnetz",$D7)),OR($W7="Relais (potentialfrei)",$W7="Digital + Relais")),Regeln!$E$30,"")) | BI7: =IF($A7="","",IF($AG7=0,"Kein Vorhaben",CHOOSE(MAX(AI7:BH7)+1,"Weiterverwendbar","Nachrüsten","Austausch"))) | BJ7: =IF($A7="","",_xlfn.TEXTJOIN(", ",TRUE(),IF(AI7<>"",AI$3,""),IF(AJ7<>"",AJ$3,""),IF(AK7<>"",AK$3,""),IF(AL7<>"",AL$3,""),IF(AM7<>"",AM$3,""),IF(AN7<>"",AN$3,""),IF(AO7<>"",AO$3,""),IF(AP7<>"",AP$3,""),IF(AQ7<>"",AQ$3,""),IF(AR7<>"",AR$3,""),IF(AS7<>"",AS$3,""),IF(AT7<>"",AT$3,""),IF(AU7<>"",AU$3,""),IF(AV7<>"",AV$3,""),IF(AW7<>"",AW$3,""),IF(AX7<>"",AX$3,""),IF(AY7<>"",AY$3,""),IF(AZ7<>"",AZ$3,""),IF(BA7<>"",BA$3,""),IF(BB7<>"",BB$3,""),IF(BC7<>"",BC$3,""),IF(BD7<>"",BD$3,""),IF(BE7<>"",BE$3,""),IF(BF7<>"",BF$3,""),IF(BG7<>"",BG$3,""),IF(BH7<>"",BH$3,""))) | BK7: =IF(OR($A7="",$AE7=""),"",IF(BI7=$AE7,"Ja","Nein")) | BL7: =IF($A7="","",IF(NOT(ISNUMBER(SEARCH("westnetz",$D7))),"–",IF($I7="Ja",IF($K7="Modul 2","MK 8 (Kaskade: Z1 SteuVE, Z2 Haushalt)","MK 2 (Überschuss)"),IF($K7="Modul 2","MK 0 + eigener Zählpunkt SteuVE","MK 0"))))
AG8: =IF($A8="","",COUNTIF($E8:$I8,"Ja")) | AH8: =IF($A8="","",IF(AND(COUNTIF($E8:$H8,"Ja")>0,N($J8)>=4.2),"Ja","Nein")) | AI8: =IF($A8="","",IF(AND(OR($L8="DIN 43853 Zählertafel ohne Schutzklasse II",$L8="DIN 43853 Norm-Zählertafel (Schutzklasse II)",$L8="DIN 43870 Norm-Zählertafel mit Vorsicherung"),$AG8>0),Regeln!$E$5,"")) | AJ8: =IF($A8="","",IF(AND(OR($L8="DIN 43870 Zählerschrank, Trennvorrichtung im AAR",$L8="DIN 43870 Zählerschrank, NH-Sicherung im NAR"),OR($AA8="unter 10 mm² oder starr",$AA8="Unbekannt",$AA8=""),$AG8>0),Regeln!$E$6,"")) | AK8: =IF($A8="","",IF(AND($V8="Nein",$AG8>0),Regeln!$E$7,"")) | AL8: =IF($A8="","",IF(AND(OR($AH8="Ja",$I8="Ja"),$O8="Nein"),Regeln!$E$8,"")) | AM8: =IF($A8="","",IF(AND($K8="Modul 2",N($N8)<1),Regeln!$E$9,"")) | AN8: =IF($A8="","",IF(AND($P8="Nein",$AG8>0,OR(ISNUMBER(SEARCH("westnetz",$D8)),$M8="3-Punkt")),Regeln!$E$10,"")) | AO8: =IF($A8="","",IF(AND($Q8="Nein",$AG8>0),Regeln!$E$11,"")) | AP8: =IF($A8="","",IF(AND($R8="1-phasig",OR(N($J8)>4.6,$I8="Ja")),Regeln!$E$12,"")) | AQ8: =IF($A8="","",IF(OR($U8="Nein",$U8="Unbekannt"),Regeln!$E$13,"")) | AR8: =IF($A8="","",IF(OR($S8="TN-C",$S8="Unbekannt"),Regeln!$E$14,"")) | AS8: =IF($A8="","",IF(AND(N($T8)>0,N($T8)<50,$AG8>=2),Regeln!$E$15,"")) | AT8: =IF($A8="","",IF(AND($E8="Ja",N($J8)>12),Regeln!$E$16,"")) | AU8: =IF($A8="","",IF($L8="Unbekannt",Regeln!$E$17,"")) | AV8: =IF($A8="","",IF(AND(OR($L8="DIN 43870 Zählerschrank, Trennvorrichtung im AAR",$L8="DIN 43870 Zählerschrank, NH-Sicherung im NAR"),$AG8>0),Regeln!$E$18,"")) | AW8: =IF($A8="","",IF(AND(ISNUMBER(SEARCH("westnetz",$D8)),OR($AH8="Ja",$I8="Ja"),$X8="Nein"),Regeln!$E$19,"")) | AX8: =IF($A8="","",IF(AND(ISNUMBER(SEARCH("westnetz",$D8)),OR($W8="Relais (potentialfrei)",$W8="Digital + Relais",AND($I8="Ja",N($AC8)>=25)),$Y8="Nein"),Regeln!$E$20,"")) | AY8: =IF($A8="","",IF(AND(ISNUMBER(SEARCH("westnetz",$D8)),OR($W8="Digital (RJ45 / EEBUS)",$W8="Digital + Relais"),$Z8="Nein"),Regeln!$E$21,"")) | AZ8: =IF($A8="","",IF(AND(ISNUMBER(SEARCH("westnetz",$D8)),N($AB8)>30),Regeln!$E$22,"")) | BA8: =IF($A8="","",IF(AND($AA8="10 mm² flexibel",N($AB8)*1000/(SQRT(3)*400)>32),Regeln!$E$23,"")) | BB8: =IF($A8="","",IF(AND(ISNUMBER(SEARCH("westnetz",$D8)),$I8="Ja",N($AC8)>=25),Regeln!$E$24,"")) | BC8: =IF($A8="","",IF(AND(ISNUMBER(SEARCH("westnetz",$D8)),$I8="Ja",OR($AH8="Ja",N($AC8)>7)),Regeln!$E$25,"")) | BD8: =IF($A8="","",IF(AND(ISNUMBER(SEARCH("westnetz",$D8)),$AH8="Ja"),Regeln!$E$26,"")) | BE8: =IF($A8="","",IF(AND(ISNUMBER(SEARCH("westnetz",$D8)),OR($W8="Relais (potentialfrei)",$W8="Digital + Relais"),$M8="3-Punkt",$AD8="Nein"),Regeln!$E$27,"")) | BF8: =IF($A8="","",IF(AND(ISNUMBER(SEARCH("westnetz",$D8)),$I8="Ja"),Regeln!$E$28,"")) | BG8: =IF($A8="","",IF(AND(ISNUMBER(SEARCH("westnetz",$D8)),$H8="Ja"),Regeln!$E$29,"")) | BH8: =IF($A8="","",IF(AND(ISNUMBER(SEARCH("westnetz",$D8)),OR($W8="Relais (potentialfrei)",$W8="Digital + Relais")),Regeln!$E$30,"")) | BI8: =IF($A8="","",IF($AG8=0,"Kein Vorhaben",CHOOSE(MAX(AI8:BH8)+1,"Weiterverwendbar","Nachrüsten","Austausch"))) | BJ8: =IF($A8="","",_xlfn.TEXTJOIN(", ",TRUE(),IF(AI8<>"",AI$3,""),IF(AJ8<>"",AJ$3,""),IF(AK8<>"",AK$3,""),IF(AL8<>"",AL$3,""),IF(AM8<>"",AM$3,""),IF(AN8<>"",AN$3,""),IF(AO8<>"",AO$3,""),IF(AP8<>"",AP$3,""),IF(AQ8<>"",AQ$3,""),IF(AR8<>"",AR$3,""),IF(AS8<>"",AS$3,""),IF(AT8<>"",AT$3,""),IF(AU8<>"",AU$3,""),IF(AV8<>"",AV$3,""),IF(AW8<>"",AW$3,""),IF(AX8<>"",AX$3,""),IF(AY8<>"",AY$3,""),IF(AZ8<>"",AZ$3,""),IF(BA8<>"",BA$3,""),IF(BB8<>"",BB$3,""),IF(BC8<>"",BC$3,""),IF(BD8<>"",BD$3,""),IF(BE8<>"",BE$3,""),IF(BF8<>"",BF$3,""),IF(BG8<>"",BG$3,""),IF(BH8<>"",BH$3,""))) | BK8: =IF(OR($A8="",$AE8=""),"",IF(BI8=$AE8,"Ja","Nein")) | BL8: =IF($A8="","",IF(NOT(ISNUMBER(SEARCH("westnetz",$D8))),"–",IF($I8="Ja",IF($K8="Modul 2","MK 8 (Kaskade: Z1 SteuVE, Z2 Haushalt)","MK 2 (Überschuss)"),IF($K8="Modul 2","MK 0 + eigener Zählpunkt SteuVE","MK 0"))))
AG9: =IF($A9="","",COUNTIF($E9:$I9,"Ja")) | AH9: =IF($A9="","",IF(AND(COUNTIF($E9:$H9,"Ja")>0,N($J9)>=4.2),"Ja","Nein")) | AI9: =IF($A9="","",IF(AND(OR($L9="DIN 43853 Zählertafel ohne Schutzklasse II",$L9="DIN 43853 Norm-Zählertafel (Schutzklasse II)",$L9="DIN 43870 Norm-Zählertafel mit Vorsicherung"),$AG9>0),Regeln!$E$5,"")) | AJ9: =IF($A9="","",IF(AND(OR($L9="DIN 43870 Zählerschrank, Trennvorrichtung im AAR",$L9="DIN 43870 Zählerschrank, NH-Sicherung im NAR"),OR($AA9="unter 10 mm² oder starr",$AA9="Unbekannt",$AA9=""),$AG9>0),Regeln!$E$6,"")) | AK9: =IF($A9="","",IF(AND($V9="Nein",$AG9>0),Regeln!$E$7,"")) | AL9: =IF($A9="","",IF(AND(OR($AH9="Ja",$I9="Ja"),$O9="Nein"),Regeln!$E$8,"")) | AM9: =IF($A9="","",IF(AND($K9="Modul 2",N($N9)<1),Regeln!$E$9,"")) | AN9: =IF($A9="","",IF(AND($P9="Nein",$AG9>0,OR(ISNUMBER(SEARCH("westnetz",$D9)),$M9="3-Punkt")),Regeln!$E$10,"")) | AO9: =IF($A9="","",IF(AND($Q9="Nein",$AG9>0),Regeln!$E$11,"")) | AP9: =IF($A9="","",IF(AND($R9="1-phasig",OR(N($J9)>4.6,$I9="Ja")),Regeln!$E$12,"")) | AQ9: =IF($A9="","",IF(OR($U9="Nein",$U9="Unbekannt"),Regeln!$E$13,"")) | AR9: =IF($A9="","",IF(OR($S9="TN-C",$S9="Unbekannt"),Regeln!$E$14,"")) | AS9: =IF($A9="","",IF(AND(N($T9)>0,N($T9)<50,$AG9>=2),Regeln!$E$15,"")) | AT9: =IF($A9="","",IF(AND($E9="Ja",N($J9)>12),Regeln!$E$16,"")) | AU9: =IF($A9="","",IF($L9="Unbekannt",Regeln!$E$17,"")) | AV9: =IF($A9="","",IF(AND(OR($L9="DIN 43870 Zählerschrank, Trennvorrichtung im AAR",$L9="DIN 43870 Zählerschrank, NH-Sicherung im NAR"),$AG9>0),Regeln!$E$18,"")) | AW9: =IF($A9="","",IF(AND(ISNUMBER(SEARCH("westnetz",$D9)),OR($AH9="Ja",$I9="Ja"),$X9="Nein"),Regeln!$E$19,"")) | AX9: =IF($A9="","",IF(AND(ISNUMBER(SEARCH("westnetz",$D9)),OR($W9="Relais (potentialfrei)",$W9="Digital + Relais",AND($I9="Ja",N($AC9)>=25)),$Y9="Nein"),Regeln!$E$20,"")) | AY9: =IF($A9="","",IF(AND(ISNUMBER(SEARCH("westnetz",$D9)),OR($W9="Digital (RJ45 / EEBUS)",$W9="Digital + Relais"),$Z9="Nein"),Regeln!$E$21,"")) | AZ9: =IF($A9="","",IF(AND(ISNUMBER(SEARCH("westnetz",$D9)),N($AB9)>30),Regeln!$E$22,"")) | BA9: =IF($A9="","",IF(AND($AA9="10 mm² flexibel",N($AB9)*1000/(SQRT(3)*400)>32),Regeln!$E$23,"")) | BB9: =IF($A9="","",IF(AND(ISNUMBER(SEARCH("westnetz",$D9)),$I9="Ja",N($AC9)>=25),Regeln!$E$24,"")) | BC9: =IF($A9="","",IF(AND(ISNUMBER(SEARCH("westnetz",$D9)),$I9="Ja",OR($AH9="Ja",N($AC9)>7)),Regeln!$E$25,"")) | BD9: =IF($A9="","",IF(AND(ISNUMBER(SEARCH("westnetz",$D9)),$AH9="Ja"),Regeln!$E$26,"")) | BE9: =IF($A9="","",IF(AND(ISNUMBER(SEARCH("westnetz",$D9)),OR($W9="Relais (potentialfrei)",$W9="Digital + Relais"),$M9="3-Punkt",$AD9="Nein"),Regeln!$E$27,"")) | BF9: =IF($A9="","",IF(AND(ISNUMBER(SEARCH("westnetz",$D9)),$I9="Ja"),Regeln!$E$28,"")) | BG9: =IF($A9="","",IF(AND(ISNUMBER(SEARCH("westnetz",$D9)),$H9="Ja"),Regeln!$E$29,"")) | BH9: =IF($A9="","",IF(AND(ISNUMBER(SEARCH("westnetz",$D9)),OR($W9="Relais (potentialfrei)",$W9="Digital + Relais")),Regeln!$E$30,"")) | BI9: =IF($A9="","",IF($AG9=0,"Kein Vorhaben",CHOOSE(MAX(AI9:BH9)+1,"Weiterverwendbar","Nachrüsten","Austausch"))) | BJ9: =IF($A9="","",_xlfn.TEXTJOIN(", ",TRUE(),IF(AI9<>"",AI$3,""),IF(AJ9<>"",AJ$3,""),IF(AK9<>"",AK$3,""),IF(AL9<>"",AL$3,""),IF(AM9<>"",AM$3,""),IF(AN9<>"",AN$3,""),IF(AO9<>"",AO$3,""),IF(AP9<>"",AP$3,""),IF(AQ9<>"",AQ$3,""),IF(AR9<>"",AR$3,""),IF(AS9<>"",AS$3,""),IF(AT9<>"",AT$3,""),IF(AU9<>"",AU$3,""),IF(AV9<>"",AV$3,""),IF(AW9<>"",AW$3,""),IF(AX9<>"",AX$3,""),IF(AY9<>"",AY$3,""),IF(AZ9<>"",AZ$3,""),IF(BA9<>"",BA$3,""),IF(BB9<>"",BB$3,""),IF(BC9<>"",BC$3,""),IF(BD9<>"",BD$3,""),IF(BE9<>"",BE$3,""),IF(BF9<>"",BF$3,""),IF(BG9<>"",BG$3,""),IF(BH9<>"",BH$3,""))) | BK9: =IF(OR($A9="",$AE9=""),"",IF(BI9=$AE9,"Ja","Nein")) | BL9: =IF($A9="","",IF(NOT(ISNUMBER(SEARCH("westnetz",$D9))),"–",IF($I9="Ja",IF($K9="Modul 2","MK 8 (Kaskade: Z1 SteuVE, Z2 Haushalt)","MK 2 (Überschuss)"),IF($K9="Modul 2","MK 0 + eigener Zählpunkt SteuVE","MK 0"))))
AG10: =IF($A10="","",COUNTIF($E10:$I10,"Ja")) | AH10: =IF($A10="","",IF(AND(COUNTIF($E10:$H10,"Ja")>0,N($J10)>=4.2),"Ja","Nein")) | AI10: =IF($A10="","",IF(AND(OR($L10="DIN 43853 Zählertafel ohne Schutzklasse II",$L10="DIN 43853 Norm-Zählertafel (Schutzklasse II)",$L10="DIN 43870 Norm-Zählertafel mit Vorsicherung"),$AG10>0),Regeln!$E$5,"")) | AJ10: =IF($A10="","",IF(AND(OR($L10="DIN 43870 Zählerschrank, Trennvorrichtung im AAR",$L10="DIN 43870 Zählerschrank, NH-Sicherung im NAR"),OR($AA10="unter 10 mm² oder starr",$AA10="Unbekannt",$AA10=""),$AG10>0),Regeln!$E$6,"")) | AK10: =IF($A10="","",IF(AND($V10="Nein",$AG10>0),Regeln!$E$7,"")) | AL10: =IF($A10="","",IF(AND(OR($AH10="Ja",$I10="Ja"),$O10="Nein"),Regeln!$E$8,"")) | AM10: =IF($A10="","",IF(AND($K10="Modul 2",N($N10)<1),Regeln!$E$9,"")) | AN10: =IF($A10="","",IF(AND($P10="Nein",$AG10>0,OR(ISNUMBER(SEARCH("westnetz",$D10)),$M10="3-Punkt")),Regeln!$E$10,"")) | AO10: =IF($A10="","",IF(AND($Q10="Nein",$AG10>0),Regeln!$E$11,"")) | AP10: =IF($A10="","",IF(AND($R10="1-phasig",OR(N($J10)>4.6,$I10="Ja")),Regeln!$E$12,"")) | AQ10: =IF($A10="","",IF(OR($U10="Nein",$U10="Unbekannt"),Regeln!$E$13,"")) | AR10: =IF($A10="","",IF(OR($S10="TN-C",$S10="Unbekannt"),Regeln!$E$14,"")) | AS10: =IF($A10="","",IF(AND(N($T10)>0,N($T10)<50,$AG10>=2),Regeln!$E$15,"")) | AT10: =IF($A10="","",IF(AND($E10="Ja",N($J10)>12),Regeln!$E$16,"")) | AU10: =IF($A10="","",IF($L10="Unbekannt",Regeln!$E$17,"")) | AV10: =IF($A10="","",IF(AND(OR($L10="DIN 43870 Zählerschrank, Trennvorrichtung im AAR",$L10="DIN 43870 Zählerschrank, NH-Sicherung im NAR"),$AG10>0),Regeln!$E$18,"")) | AW10: =IF($A10="","",IF(AND(ISNUMBER(SEARCH("westnetz",$D10)),OR($AH10="Ja",$I10="Ja"),$X10="Nein"),Regeln!$E$19,"")) | AX10: =IF($A10="","",IF(AND(ISNUMBER(SEARCH("westnetz",$D10)),OR($W10="Relais (potentialfrei)",$W10="Digital + Relais",AND($I10="Ja",N($AC10)>=25)),$Y10="Nein"),Regeln!$E$20,"")) | AY10: =IF($A10="","",IF(AND(ISNUMBER(SEARCH("westnetz",$D10)),OR($W10="Digital (RJ45 / EEBUS)",$W10="Digital + Relais"),$Z10="Nein"),Regeln!$E$21,"")) | AZ10: =IF($A10="","",IF(AND(ISNUMBER(SEARCH("westnetz",$D10)),N($AB10)>30),Regeln!$E$22,"")) | BA10: =IF($A10="","",IF(AND($AA10="10 mm² flexibel",N($AB10)*1000/(SQRT(3)*400)>32),Regeln!$E$23,"")) | BB10: =IF($A10="","",IF(AND(ISNUMBER(SEARCH("westnetz",$D10)),$I10="Ja",N($AC10)>=25),Regeln!$E$24,"")) | BC10: =IF($A10="","",IF(AND(ISNUMBER(SEARCH("westnetz",$D10)),$I10="Ja",OR($AH10="Ja",N($AC10)>7)),Regeln!$E$25,"")) | BD10: =IF($A10="","",IF(AND(ISNUMBER(SEARCH("westnetz",$D10)),$AH10="Ja"),Regeln!$E$26,"")) | BE10: =IF($A10="","",IF(AND(ISNUMBER(SEARCH("westnetz",$D10)),OR($W10="Relais (potentialfrei)",$W10="Digital + Relais"),$M10="3-Punkt",$AD10="Nein"),Regeln!$E$27,"")) | BF10: =IF($A10="","",IF(AND(ISNUMBER(SEARCH("westnetz",$D10)),$I10="Ja"),Regeln!$E$28,"")) | BG10: =IF($A10="","",IF(AND(ISNUMBER(SEARCH("westnetz",$D10)),$H10="Ja"),Regeln!$E$29,"")) | BH10: =IF($A10="","",IF(AND(ISNUMBER(SEARCH("westnetz",$D10)),OR($W10="Relais (potentialfrei)",$W10="Digital + Relais")),Regeln!$E$30,"")) | BI10: =IF($A10="","",IF($AG10=0,"Kein Vorhaben",CHOOSE(MAX(AI10:BH10)+1,"Weiterverwendbar","Nachrüsten","Austausch"))) | BJ10: =IF($A10="","",_xlfn.TEXTJOIN(", ",TRUE(),IF(AI10<>"",AI$3,""),IF(AJ10<>"",AJ$3,""),IF(AK10<>"",AK$3,""),IF(AL10<>"",AL$3,""),IF(AM10<>"",AM$3,""),IF(AN10<>"",AN$3,""),IF(AO10<>"",AO$3,""),IF(AP10<>"",AP$3,""),IF(AQ10<>"",AQ$3,""),IF(AR10<>"",AR$3,""),IF(AS10<>"",AS$3,""),IF(AT10<>"",AT$3,""),IF(AU10<>"",AU$3,""),IF(AV10<>"",AV$3,""),IF(AW10<>"",AW$3,""),IF(AX10<>"",AX$3,""),IF(AY10<>"",AY$3,""),IF(AZ10<>"",AZ$3,""),IF(BA10<>"",BA$3,""),IF(BB10<>"",BB$3,""),IF(BC10<>"",BC$3,""),IF(BD10<>"",BD$3,""),IF(BE10<>"",BE$3,""),IF(BF10<>"",BF$3,""),IF(BG10<>"",BG$3,""),IF(BH10<>"",BH$3,""))) | BK10: =IF(OR($A10="",$AE10=""),"",IF(BI10=$AE10,"Ja","Nein")) | BL10: =IF($A10="","",IF(NOT(ISNUMBER(SEARCH("westnetz",$D10))),"–",IF($I10="Ja",IF($K10="Modul 2","MK 8 (Kaskade: Z1 SteuVE, Z2 Haushalt)","MK 2 (Überschuss)"),IF($K10="Modul 2","MK 0 + eigener Zählpunkt SteuVE","MK 0"))))
AG11: =IF($A11="","",COUNTIF($E11:$I11,"Ja")) | AH11: =IF($A11="","",IF(AND(COUNTIF($E11:$H11,"Ja")>0,N($J11)>=4.2),"Ja","Nein")) | AI11: =IF($A11="","",IF(AND(OR($L11="DIN 43853 Zählertafel ohne Schutzklasse II",$L11="DIN 43853 Norm-Zählertafel (Schutzklasse II)",$L11="DIN 43870 Norm-Zählertafel mit Vorsicherung"),$AG11>0),Regeln!$E$5,"")) | AJ11: =IF($A11="","",IF(AND(OR($L11="DIN 43870 Zählerschrank, Trennvorrichtung im AAR",$L11="DIN 43870 Zählerschrank, NH-Sicherung im NAR"),OR($AA11="unter 10 mm² oder starr",$AA11="Unbekannt",$AA11=""),$AG11>0),Regeln!$E$6,"")) | AK11: =IF($A11="","",IF(AND($V11="Nein",$AG11>0),Regeln!$E$7,"")) | AL11: =IF($A11="","",IF(AND(OR($AH11="Ja",$I11="Ja"),$O11="Nein"),Regeln!$E$8,"")) | AM11: =IF($A11="","",IF(AND($K11="Modul 2",N($N11)<1),Regeln!$E$9,"")) | AN11: =IF($A11="","",IF(AND($P11="Nein",$AG11>0,OR(ISNUMBER(SEARCH("westnetz",$D11)),$M11="3-Punkt")),Regeln!$E$10,"")) | AO11: =IF($A11="","",IF(AND($Q11="Nein",$AG11>0),Regeln!$E$11,"")) | AP11: =IF($A11="","",IF(AND($R11="1-phasig",OR(N($J11)>4.6,$I11="Ja")),Regeln!$E$12,"")) | AQ11: =IF($A11="","",IF(OR($U11="Nein",$U11="Unbekannt"),Regeln!$E$13,"")) | AR11: =IF($A11="","",IF(OR($S11="TN-C",$S11="Unbekannt"),Regeln!$E$14,"")) | AS11: =IF($A11="","",IF(AND(N($T11)>0,N($T11)<50,$AG11>=2),Regeln!$E$15,"")) | AT11: =IF($A11="","",IF(AND($E11="Ja",N($J11)>12),Regeln!$E$16,"")) | AU11: =IF($A11="","",IF($L11="Unbekannt",Regeln!$E$17,"")) | AV11: =IF($A11="","",IF(AND(OR($L11="DIN 43870 Zählerschrank, Trennvorrichtung im AAR",$L11="DIN 43870 Zählerschrank, NH-Sicherung im NAR"),$AG11>0),Regeln!$E$18,"")) | AW11: =IF($A11="","",IF(AND(ISNUMBER(SEARCH("westnetz",$D11)),OR($AH11="Ja",$I11="Ja"),$X11="Nein"),Regeln!$E$19,"")) | AX11: =IF($A11="","",IF(AND(ISNUMBER(SEARCH("westnetz",$D11)),OR($W11="Relais (potentialfrei)",$W11="Digital + Relais",AND($I11="Ja",N($AC11)>=25)),$Y11="Nein"),Regeln!$E$20,"")) | AY11: =IF($A11="","",IF(AND(ISNUMBER(SEARCH("westnetz",$D11)),OR($W11="Digital (RJ45 / EEBUS)",$W11="Digital + Relais"),$Z11="Nein"),Regeln!$E$21,"")) | AZ11: =IF($A11="","",IF(AND(ISNUMBER(SEARCH("westnetz",$D11)),N($AB11)>30),Regeln!$E$22,"")) | BA11: =IF($A11="","",IF(AND($AA11="10 mm² flexibel",N($AB11)*1000/(SQRT(3)*400)>32),Regeln!$E$23,"")) | BB11: =IF($A11="","",IF(AND(ISNUMBER(SEARCH("westnetz",$D11)),$I11="Ja",N($AC11)>=25),Regeln!$E$24,"")) | BC11: =IF($A11="","",IF(AND(ISNUMBER(SEARCH("westnetz",$D11)),$I11="Ja",OR($AH11="Ja",N($AC11)>7)),Regeln!$E$25,"")) | BD11: =IF($A11="","",IF(AND(ISNUMBER(SEARCH("westnetz",$D11)),$AH11="Ja"),Regeln!$E$26,"")) | BE11: =IF($A11="","",IF(AND(ISNUMBER(SEARCH("westnetz",$D11)),OR($W11="Relais (potentialfrei)",$W11="Digital + Relais"),$M11="3-Punkt",$AD11="Nein"),Regeln!$E$27,"")) | BF11: =IF($A11="","",IF(AND(ISNUMBER(SEARCH("westnetz",$D11)),$I11="Ja"),Regeln!$E$28,"")) | BG11: =IF($A11="","",IF(AND(ISNUMBER(SEARCH("westnetz",$D11)),$H11="Ja"),Regeln!$E$29,"")) | BH11: =IF($A11="","",IF(AND(ISNUMBER(SEARCH("westnetz",$D11)),OR($W11="Relais (potentialfrei)",$W11="Digital + Relais")),Regeln!$E$30,"")) | BI11: =IF($A11="","",IF($AG11=0,"Kein Vorhaben",CHOOSE(MAX(AI11:BH11)+1,"Weiterverwendbar","Nachrüsten","Austausch"))) | BJ11: =IF($A11="","",_xlfn.TEXTJOIN(", ",TRUE(),IF(AI11<>"",AI$3,""),IF(AJ11<>"",AJ$3,""),IF(AK11<>"",AK$3,""),IF(AL11<>"",AL$3,""),IF(AM11<>"",AM$3,""),IF(AN11<>"",AN$3,""),IF(AO11<>"",AO$3,""),IF(AP11<>"",AP$3,""),IF(AQ11<>"",AQ$3,""),IF(AR11<>"",AR$3,""),IF(AS11<>"",AS$3,""),IF(AT11<>"",AT$3,""),IF(AU11<>"",AU$3,""),IF(AV11<>"",AV$3,""),IF(AW11<>"",AW$3,""),IF(AX11<>"",AX$3,""),IF(AY11<>"",AY$3,""),IF(AZ11<>"",AZ$3,""),IF(BA11<>"",BA$3,""),IF(BB11<>"",BB$3,""),IF(BC11<>"",BC$3,""),IF(BD11<>"",BD$3,""),IF(BE11<>"",BE$3,""),IF(BF11<>"",BF$3,""),IF(BG11<>"",BG$3,""),IF(BH11<>"",BH$3,""))) | BK11: =IF(OR($A11="",$AE11=""),"",IF(BI11=$AE11,"Ja","Nein")) | BL11: =IF($A11="","",IF(NOT(ISNUMBER(SEARCH("westnetz",$D11))),"–",IF($I11="Ja",IF($K11="Modul 2","MK 8 (Kaskade: Z1 SteuVE, Z2 Haushalt)","MK 2 (Überschuss)"),IF($K11="Modul 2","MK 0 + eigener Zählpunkt SteuVE","MK 0"))))
AG12: =IF($A12="","",COUNTIF($E12:$I12,"Ja")) | AH12: =IF($A12="","",IF(AND(COUNTIF($E12:$H12,"Ja")>0,N($J12)>=4.2),"Ja","Nein")) | AI12: =IF($A12="","",IF(AND(OR($L12="DIN 43853 Zählertafel ohne Schutzklasse II",$L12="DIN 43853 Norm-Zählertafel (Schutzklasse II)",$L12="DIN 43870 Norm-Zählertafel mit Vorsicherung"),$AG12>0),Regeln!$E$5,"")) | AJ12: =IF($A12="","",IF(AND(OR($L12="DIN 43870 Zählerschrank, Trennvorrichtung im AAR",$L12="DIN 43870 Zählerschrank, NH-Sicherung im NAR"),OR($AA12="unter 10 mm² oder starr",$AA12="Unbekannt",$AA12=""),$AG12>0),Regeln!$E$6,"")) | AK12: =IF($A12="","",IF(AND($V12="Nein",$AG12>0),Regeln!$E$7,"")) | AL12: =IF($A12="","",IF(AND(OR($AH12="Ja",$I12="Ja"),$O12="Nein"),Regeln!$E$8,"")) | AM12: =IF($A12="","",IF(AND($K12="Modul 2",N($N12)<1),Regeln!$E$9,"")) | AN12: =IF($A12="","",IF(AND($P12="Nein",$AG12>0,OR(ISNUMBER(SEARCH("westnetz",$D12)),$M12="3-Punkt")),Regeln!$E$10,"")) | AO12: =IF($A12="","",IF(AND($Q12="Nein",$AG12>0),Regeln!$E$11,"")) | AP12: =IF($A12="","",IF(AND($R12="1-phasig",OR(N($J12)>4.6,$I12="Ja")),Regeln!$E$12,"")) | AQ12: =IF($A12="","",IF(OR($U12="Nein",$U12="Unbekannt"),Regeln!$E$13,"")) | AR12: =IF($A12="","",IF(OR($S12="TN-C",$S12="Unbekannt"),Regeln!$E$14,"")) | AS12: =IF($A12="","",IF(AND(N($T12)>0,N($T12)<50,$AG12>=2),Regeln!$E$15,"")) | AT12: =IF($A12="","",IF(AND($E12="Ja",N($J12)>12),Regeln!$E$16,"")) | AU12: =IF($A12="","",IF($L12="Unbekannt",Regeln!$E$17,"")) | AV12: =IF($A12="","",IF(AND(OR($L12="DIN 43870 Zählerschrank, Trennvorrichtung im AAR",$L12="DIN 43870 Zählerschrank, NH-Sicherung im NAR"),$AG12>0),Regeln!$E$18,"")) | AW12: =IF($A12="","",IF(AND(ISNUMBER(SEARCH("westnetz",$D12)),OR($AH12="Ja",$I12="Ja"),$X12="Nein"),Regeln!$E$19,"")) | AX12: =IF($A12="","",IF(AND(ISNUMBER(SEARCH("westnetz",$D12)),OR($W12="Relais (potentialfrei)",$W12="Digital + Relais",AND($I12="Ja",N($AC12)>=25)),$Y12="Nein"),Regeln!$E$20,"")) | AY12: =IF($A12="","",IF(AND(ISNUMBER(SEARCH("westnetz",$D12)),OR($W12="Digital (RJ45 / EEBUS)",$W12="Digital + Relais"),$Z12="Nein"),Regeln!$E$21,"")) | AZ12: =IF($A12="","",IF(AND(ISNUMBER(SEARCH("westnetz",$D12)),N($AB12)>30),Regeln!$E$22,"")) | BA12: =IF($A12="","",IF(AND($AA12="10 mm² flexibel",N($AB12)*1000/(SQRT(3)*400)>32),Regeln!$E$23,"")) | BB12: =IF($A12="","",IF(AND(ISNUMBER(SEARCH("westnetz",$D12)),$I12="Ja",N($AC12)>=25),Regeln!$E$24,"")) | BC12: =IF($A12="","",IF(AND(ISNUMBER(SEARCH("westnetz",$D12)),$I12="Ja",OR($AH12="Ja",N($AC12)>7)),Regeln!$E$25,"")) | BD12: =IF($A12="","",IF(AND(ISNUMBER(SEARCH("westnetz",$D12)),$AH12="Ja"),Regeln!$E$26,"")) | BE12: =IF($A12="","",IF(AND(ISNUMBER(SEARCH("westnetz",$D12)),OR($W12="Relais (potentialfrei)",$W12="Digital + Relais"),$M12="3-Punkt",$AD12="Nein"),Regeln!$E$27,"")) | BF12: =IF($A12="","",IF(AND(ISNUMBER(SEARCH("westnetz",$D12)),$I12="Ja"),Regeln!$E$28,"")) | BG12: =IF($A12="","",IF(AND(ISNUMBER(SEARCH("westnetz",$D12)),$H12="Ja"),Regeln!$E$29,"")) | BH12: =IF($A12="","",IF(AND(ISNUMBER(SEARCH("westnetz",$D12)),OR($W12="Relais (potentialfrei)",$W12="Digital + Relais")),Regeln!$E$30,"")) | BI12: =IF($A12="","",IF($AG12=0,"Kein Vorhaben",CHOOSE(MAX(AI12:BH12)+1,"Weiterverwendbar","Nachrüsten","Austausch"))) | BJ12: =IF($A12="","",_xlfn.TEXTJOIN(", ",TRUE(),IF(AI12<>"",AI$3,""),IF(AJ12<>"",AJ$3,""),IF(AK12<>"",AK$3,""),IF(AL12<>"",AL$3,""),IF(AM12<>"",AM$3,""),IF(AN12<>"",AN$3,""),IF(AO12<>"",AO$3,""),IF(AP12<>"",AP$3,""),IF(AQ12<>"",AQ$3,""),IF(AR12<>"",AR$3,""),IF(AS12<>"",AS$3,""),IF(AT12<>"",AT$3,""),IF(AU12<>"",AU$3,""),IF(AV12<>"",AV$3,""),IF(AW12<>"",AW$3,""),IF(AX12<>"",AX$3,""),IF(AY12<>"",AY$3,""),IF(AZ12<>"",AZ$3,""),IF(BA12<>"",BA$3,""),IF(BB12<>"",BB$3,""),IF(BC12<>"",BC$3,""),IF(BD12<>"",BD$3,""),IF(BE12<>"",BE$3,""),IF(BF12<>"",BF$3,""),IF(BG12<>"",BG$3,""),IF(BH12<>"",BH$3,""))) | BK12: =IF(OR($A12="",$AE12=""),"",IF(BI12=$AE12,"Ja","Nein")) | BL12: =IF($A12="","",IF(NOT(ISNUMBER(SEARCH("westnetz",$D12))),"–",IF($I12="Ja",IF($K12="Modul 2","MK 8 (Kaskade: Z1 SteuVE, Z2 Haushalt)","MK 2 (Überschuss)"),IF($K12="Modul 2","MK 0 + eigener Zählpunkt SteuVE","MK 0"))))
AG13: =IF($A13="","",COUNTIF($E13:$I13,"Ja")) | AH13: =IF($A13="","",IF(AND(COUNTIF($E13:$H13,"Ja")>0,N($J13)>=4.2),"Ja","Nein")) | AI13: =IF($A13="","",IF(AND(OR($L13="DIN 43853 Zählertafel ohne Schutzklasse II",$L13="DIN 43853 Norm-Zählertafel (Schutzklasse II)",$L13="DIN 43870 Norm-Zählertafel mit Vorsicherung"),$AG13>0),Regeln!$E$5,"")) | AJ13: =IF($A13="","",IF(AND(OR($L13="DIN 43870 Zählerschrank, Trennvorrichtung im AAR",$L13="DIN 43870 Zählerschrank, NH-Sicherung im NAR"),OR($AA13="unter 10 mm² oder starr",$AA13="Unbekannt",$AA13=""),$AG13>0),Regeln!$E$6,"")) | AK13: =IF($A13="","",IF(AND($V13="Nein",$AG13>0),Regeln!$E$7,"")) | AL13: =IF($A13="","",IF(AND(OR($AH13="Ja",$I13="Ja"),$O13="Nein"),Regeln!$E$8,"")) | AM13: =IF($A13="","",IF(AND($K13="Modul 2",N($N13)<1),Regeln!$E$9,"")) | AN13: =IF($A13="","",IF(AND($P13="Nein",$AG13>0,OR(ISNUMBER(SEARCH("westnetz",$D13)),$M13="3-Punkt")),Regeln!$E$10,"")) | AO13: =IF($A13="","",IF(AND($Q13="Nein",$AG13>0),Regeln!$E$11,"")) | AP13: =IF($A13="","",IF(AND($R13="1-phasig",OR(N($J13)>4.6,$I13="Ja")),Regeln!$E$12,"")) | AQ13: =IF($A13="","",IF(OR($U13="Nein",$U13="Unbekannt"),Regeln!$E$13,"")) | AR13: =IF($A13="","",IF(OR($S13="TN-C",$S13="Unbekannt"),Regeln!$E$14,"")) | AS13: =IF($A13="","",IF(AND(N($T13)>0,N($T13)<50,$AG13>=2),Regeln!$E$15,"")) | AT13: =IF($A13="","",IF(AND($E13="Ja",N($J13)>12),Regeln!$E$16,"")) | AU13: =IF($A13="","",IF($L13="Unbekannt",Regeln!$E$17,"")) | AV13: =IF($A13="","",IF(AND(OR($L13="DIN 43870 Zählerschrank, Trennvorrichtung im AAR",$L13="DIN 43870 Zählerschrank, NH-Sicherung im NAR"),$AG13>0),Regeln!$E$18,"")) | AW13: =IF($A13="","",IF(AND(ISNUMBER(SEARCH("westnetz",$D13)),OR($AH13="Ja",$I13="Ja"),$X13="Nein"),Regeln!$E$19,"")) | AX13: =IF($A13="","",IF(AND(ISNUMBER(SEARCH("westnetz",$D13)),OR($W13="Relais (potentialfrei)",$W13="Digital + Relais",AND($I13="Ja",N($AC13)>=25)),$Y13="Nein"),Regeln!$E$20,"")) | AY13: =IF($A13="","",IF(AND(ISNUMBER(SEARCH("westnetz",$D13)),OR($W13="Digital (RJ45 / EEBUS)",$W13="Digital + Relais"),$Z13="Nein"),Regeln!$E$21,"")) | AZ13: =IF($A13="","",IF(AND(ISNUMBER(SEARCH("westnetz",$D13)),N($AB13)>30),Regeln!$E$22,"")) | BA13: =IF($A13="","",IF(AND($AA13="10 mm² flexibel",N($AB13)*1000/(SQRT(3)*400)>32),Regeln!$E$23,"")) | BB13: =IF($A13="","",IF(AND(ISNUMBER(SEARCH("westnetz",$D13)),$I13="Ja",N($AC13)>=25),Regeln!$E$24,"")) | BC13: =IF($A13="","",IF(AND(ISNUMBER(SEARCH("westnetz",$D13)),$I13="Ja",OR($AH13="Ja",N($AC13)>7)),Regeln!$E$25,"")) | BD13: =IF($A13="","",IF(AND(ISNUMBER(SEARCH("westnetz",$D13)),$AH13="Ja"),Regeln!$E$26,"")) | BE13: =IF($A13="","",IF(AND(ISNUMBER(SEARCH("westnetz",$D13)),OR($W13="Relais (potentialfrei)",$W13="Digital + Relais"),$M13="3-Punkt",$AD13="Nein"),Regeln!$E$27,"")) | BF13: =IF($A13="","",IF(AND(ISNUMBER(SEARCH("westnetz",$D13)),$I13="Ja"),Regeln!$E$28,"")) | BG13: =IF($A13="","",IF(AND(ISNUMBER(SEARCH("westnetz",$D13)),$H13="Ja"),Regeln!$E$29,"")) | BH13: =IF($A13="","",IF(AND(ISNUMBER(SEARCH("westnetz",$D13)),OR($W13="Relais (potentialfrei)",$W13="Digital + Relais")),Regeln!$E$30,"")) | BI13: =IF($A13="","",IF($AG13=0,"Kein Vorhaben",CHOOSE(MAX(AI13:BH13)+1,"Weiterverwendbar","Nachrüsten","Austausch"))) | BJ13: =IF($A13="","",_xlfn.TEXTJOIN(", ",TRUE(),IF(AI13<>"",AI$3,""),IF(AJ13<>"",AJ$3,""),IF(AK13<>"",AK$3,""),IF(AL13<>"",AL$3,""),IF(AM13<>"",AM$3,""),IF(AN13<>"",AN$3,""),IF(AO13<>"",AO$3,""),IF(AP13<>"",AP$3,""),IF(AQ13<>"",AQ$3,""),IF(AR13<>"",AR$3,""),IF(AS13<>"",AS$3,""),IF(AT13<>"",AT$3,""),IF(AU13<>"",AU$3,""),IF(AV13<>"",AV$3,""),IF(AW13<>"",AW$3,""),IF(AX13<>"",AX$3,""),IF(AY13<>"",AY$3,""),IF(AZ13<>"",AZ$3,""),IF(BA13<>"",BA$3,""),IF(BB13<>"",BB$3,""),IF(BC13<>"",BC$3,""),IF(BD13<>"",BD$3,""),IF(BE13<>"",BE$3,""),IF(BF13<>"",BF$3,""),IF(BG13<>"",BG$3,""),IF(BH13<>"",BH$3,""))) | BK13: =IF(OR($A13="",$AE13=""),"",IF(BI13=$AE13,"Ja","Nein")) | BL13: =IF($A13="","",IF(NOT(ISNUMBER(SEARCH("westnetz",$D13))),"–",IF($I13="Ja",IF($K13="Modul 2","MK 8 (Kaskade: Z1 SteuVE, Z2 Haushalt)","MK 2 (Überschuss)"),IF($K13="Modul 2","MK 0 + eigener Zählpunkt SteuVE","MK 0"))))
AG14: =IF($A14="","",COUNTIF($E14:$I14,"Ja")) | AH14: =IF($A14="","",IF(AND(COUNTIF($E14:$H14,"Ja")>0,N($J14)>=4.2),"Ja","Nein")) | AI14: =IF($A14="","",IF(AND(OR($L14="DIN 43853 Zählertafel ohne Schutzklasse II",$L14="DIN 43853 Norm-Zählertafel (Schutzklasse II)",$L14="DIN 43870 Norm-Zählertafel mit Vorsicherung"),$AG14>0),Regeln!$E$5,"")) | AJ14: =IF($A14="","",IF(AND(OR($L14="DIN 43870 Zählerschrank, Trennvorrichtung im AAR",$L14="DIN 43870 Zählerschrank, NH-Sicherung im NAR"),OR($AA14="unter 10 mm² oder starr",$AA14="Unbekannt",$AA14=""),$AG14>0),Regeln!$E$6,"")) | AK14: =IF($A14="","",IF(AND($V14="Nein",$AG14>0),Regeln!$E$7,"")) | AL14: =IF($A14="","",IF(AND(OR($AH14="Ja",$I14="Ja"),$O14="Nein"),Regeln!$E$8,"")) | AM14: =IF($A14="","",IF(AND($K14="Modul 2",N($N14)<1),Regeln!$E$9,"")) | AN14: =IF($A14="","",IF(AND($P14="Nein",$AG14>0,OR(ISNUMBER(SEARCH("westnetz",$D14)),$M14="3-Punkt")),Regeln!$E$10,"")) | AO14: =IF($A14="","",IF(AND($Q14="Nein",$AG14>0),Regeln!$E$11,"")) | AP14: =IF($A14="","",IF(AND($R14="1-phasig",OR(N($J14)>4.6,$I14="Ja")),Regeln!$E$12,"")) | AQ14: =IF($A14="","",IF(OR($U14="Nein",$U14="Unbekannt"),Regeln!$E$13,"")) | AR14: =IF($A14="","",IF(OR($S14="TN-C",$S14="Unbekannt"),Regeln!$E$14,"")) | AS14: =IF($A14="","",IF(AND(N($T14)>0,N($T14)<50,$AG14>=2),Regeln!$E$15,"")) | AT14: =IF($A14="","",IF(AND($E14="Ja",N($J14)>12),Regeln!$E$16,"")) | AU14: =IF($A14="","",IF($L14="Unbekannt",Regeln!$E$17,"")) | AV14: =IF($A14="","",IF(AND(OR($L14="DIN 43870 Zählerschrank, Trennvorrichtung im AAR",$L14="DIN 43870 Zählerschrank, NH-Sicherung im NAR"),$AG14>0),Regeln!$E$18,"")) | AW14: =IF($A14="","",IF(AND(ISNUMBER(SEARCH("westnetz",$D14)),OR($AH14="Ja",$I14="Ja"),$X14="Nein"),Regeln!$E$19,"")) | AX14: =IF($A14="","",IF(AND(ISNUMBER(SEARCH("westnetz",$D14)),OR($W14="Relais (potentialfrei)",$W14="Digital + Relais",AND($I14="Ja",N($AC14)>=25)),$Y14="Nein"),Regeln!$E$20,"")) | AY14: =IF($A14="","",IF(AND(ISNUMBER(SEARCH("westnetz",$D14)),OR($W14="Digital (RJ45 / EEBUS)",$W14="Digital + Relais"),$Z14="Nein"),Regeln!$E$21,"")) | AZ14: =IF($A14="","",IF(AND(ISNUMBER(SEARCH("westnetz",$D14)),N($AB14)>30),Regeln!$E$22,"")) | BA14: =IF($A14="","",IF(AND($AA14="10 mm² flexibel",N($AB14)*1000/(SQRT(3)*400)>32),Regeln!$E$23,"")) | BB14: =IF($A14="","",IF(AND(ISNUMBER(SEARCH("westnetz",$D14)),$I14="Ja",N($AC14)>=25),Regeln!$E$24,"")) | BC14: =IF($A14="","",IF(AND(ISNUMBER(SEARCH("westnetz",$D14)),$I14="Ja",OR($AH14="Ja",N($AC14)>7)),Regeln!$E$25,"")) | BD14: =IF($A14="","",IF(AND(ISNUMBER(SEARCH("westnetz",$D14)),$AH14="Ja"),Regeln!$E$26,"")) | BE14: =IF($A14="","",IF(AND(ISNUMBER(SEARCH("westnetz",$D14)),OR($W14="Relais (potentialfrei)",$W14="Digital + Relais"),$M14="3-Punkt",$AD14="Nein"),Regeln!$E$27,"")) | BF14: =IF($A14="","",IF(AND(ISNUMBER(SEARCH("westnetz",$D14)),$I14="Ja"),Regeln!$E$28,"")) | BG14: =IF($A14="","",IF(AND(ISNUMBER(SEARCH("westnetz",$D14)),$H14="Ja"),Regeln!$E$29,"")) | BH14: =IF($A14="","",IF(AND(ISNUMBER(SEARCH("westnetz",$D14)),OR($W14="Relais (potentialfrei)",$W14="Digital + Relais")),Regeln!$E$30,"")) | BI14: =IF($A14="","",IF($AG14=0,"Kein Vorhaben",CHOOSE(MAX(AI14:BH14)+1,"Weiterverwendbar","Nachrüsten","Austausch"))) | BJ14: =IF($A14="","",_xlfn.TEXTJOIN(", ",TRUE(),IF(AI14<>"",AI$3,""),IF(AJ14<>"",AJ$3,""),IF(AK14<>"",AK$3,""),IF(AL14<>"",AL$3,""),IF(AM14<>"",AM$3,""),IF(AN14<>"",AN$3,""),IF(AO14<>"",AO$3,""),IF(AP14<>"",AP$3,""),IF(AQ14<>"",AQ$3,""),IF(AR14<>"",AR$3,""),IF(AS14<>"",AS$3,""),IF(AT14<>"",AT$3,""),IF(AU14<>"",AU$3,""),IF(AV14<>"",AV$3,""),IF(AW14<>"",AW$3,""),IF(AX14<>"",AX$3,""),IF(AY14<>"",AY$3,""),IF(AZ14<>"",AZ$3,""),IF(BA14<>"",BA$3,""),IF(BB14<>"",BB$3,""),IF(BC14<>"",BC$3,""),IF(BD14<>"",BD$3,""),IF(BE14<>"",BE$3,""),IF(BF14<>"",BF$3,""),IF(BG14<>"",BG$3,""),IF(BH14<>"",BH$3,""))) | BK14: =IF(OR($A14="",$AE14=""),"",IF(BI14=$AE14,"Ja","Nein")) | BL14: =IF($A14="","",IF(NOT(ISNUMBER(SEARCH("westnetz",$D14))),"–",IF($I14="Ja",IF($K14="Modul 2","MK 8 (Kaskade: Z1 SteuVE, Z2 Haushalt)","MK 2 (Überschuss)"),IF($K14="Modul 2","MK 0 + eigener Zählpunkt SteuVE","MK 0"))))
AG15: =IF($A15="","",COUNTIF($E15:$I15,"Ja")) | AH15: =IF($A15="","",IF(AND(COUNTIF($E15:$H15,"Ja")>0,N($J15)>=4.2),"Ja","Nein")) | AI15: =IF($A15="","",IF(AND(OR($L15="DIN 43853 Zählertafel ohne Schutzklasse II",$L15="DIN 43853 Norm-Zählertafel (Schutzklasse II)",$L15="DIN 43870 Norm-Zählertafel mit Vorsicherung"),$AG15>0),Regeln!$E$5,"")) | AJ15: =IF($A15="","",IF(AND(OR($L15="DIN 43870 Zählerschrank, Trennvorrichtung im AAR",$L15="DIN 43870 Zählerschrank, NH-Sicherung im NAR"),OR($AA15="unter 10 mm² oder starr",$AA15="Unbekannt",$AA15=""),$AG15>0),Regeln!$E$6,"")) | AK15: =IF($A15="","",IF(AND($V15="Nein",$AG15>0),Regeln!$E$7,"")) | AL15: =IF($A15="","",IF(AND(OR($AH15="Ja",$I15="Ja"),$O15="Nein"),Regeln!$E$8,"")) | AM15: =IF($A15="","",IF(AND($K15="Modul 2",N($N15)<1),Regeln!$E$9,"")) | AN15: =IF($A15="","",IF(AND($P15="Nein",$AG15>0,OR(ISNUMBER(SEARCH("westnetz",$D15)),$M15="3-Punkt")),Regeln!$E$10,"")) | AO15: =IF($A15="","",IF(AND($Q15="Nein",$AG15>0),Regeln!$E$11,"")) | AP15: =IF($A15="","",IF(AND($R15="1-phasig",OR(N($J15)>4.6,$I15="Ja")),Regeln!$E$12,"")) | AQ15: =IF($A15="","",IF(OR($U15="Nein",$U15="Unbekannt"),Regeln!$E$13,"")) | AR15: =IF($A15="","",IF(OR($S15="TN-C",$S15="Unbekannt"),Regeln!$E$14,"")) | AS15: =IF($A15="","",IF(AND(N($T15)>0,N($T15)<50,$AG15>=2),Regeln!$E$15,"")) | AT15: =IF($A15="","",IF(AND($E15="Ja",N($J15)>12),Regeln!$E$16,"")) | AU15: =IF($A15="","",IF($L15="Unbekannt",Regeln!$E$17,"")) | AV15: =IF($A15="","",IF(AND(OR($L15="DIN 43870 Zählerschrank, Trennvorrichtung im AAR",$L15="DIN 43870 Zählerschrank, NH-Sicherung im NAR"),$AG15>0),Regeln!$E$18,"")) | AW15: =IF($A15="","",IF(AND(ISNUMBER(SEARCH("westnetz",$D15)),OR($AH15="Ja",$I15="Ja"),$X15="Nein"),Regeln!$E$19,"")) | AX15: =IF($A15="","",IF(AND(ISNUMBER(SEARCH("westnetz",$D15)),OR($W15="Relais (potentialfrei)",$W15="Digital + Relais",AND($I15="Ja",N($AC15)>=25)),$Y15="Nein"),Regeln!$E$20,"")) | AY15: =IF($A15="","",IF(AND(ISNUMBER(SEARCH("westnetz",$D15)),OR($W15="Digital (RJ45 / EEBUS)",$W15="Digital + Relais"),$Z15="Nein"),Regeln!$E$21,"")) | AZ15: =IF($A15="","",IF(AND(ISNUMBER(SEARCH("westnetz",$D15)),N($AB15)>30),Regeln!$E$22,"")) | BA15: =IF($A15="","",IF(AND($AA15="10 mm² flexibel",N($AB15)*1000/(SQRT(3)*400)>32),Regeln!$E$23,"")) | BB15: =IF($A15="","",IF(AND(ISNUMBER(SEARCH("westnetz",$D15)),$I15="Ja",N($AC15)>=25),Regeln!$E$24,"")) | BC15: =IF($A15="","",IF(AND(ISNUMBER(SEARCH("westnetz",$D15)),$I15="Ja",OR($AH15="Ja",N($AC15)>7)),Regeln!$E$25,"")) | BD15: =IF($A15="","",IF(AND(ISNUMBER(SEARCH("westnetz",$D15)),$AH15="Ja"),Regeln!$E$26,"")) | BE15: =IF($A15="","",IF(AND(ISNUMBER(SEARCH("westnetz",$D15)),OR($W15="Relais (potentialfrei)",$W15="Digital + Relais"),$M15="3-Punkt",$AD15="Nein"),Regeln!$E$27,"")) | BF15: =IF($A15="","",IF(AND(ISNUMBER(SEARCH("westnetz",$D15)),$I15="Ja"),Regeln!$E$28,"")) | BG15: =IF($A15="","",IF(AND(ISNUMBER(SEARCH("westnetz",$D15)),$H15="Ja"),Regeln!$E$29,"")) | BH15: =IF($A15="","",IF(AND(ISNUMBER(SEARCH("westnetz",$D15)),OR($W15="Relais (potentialfrei)",$W15="Digital + Relais")),Regeln!$E$30,"")) | BI15: =IF($A15="","",IF($AG15=0,"Kein Vorhaben",CHOOSE(MAX(AI15:BH15)+1,"Weiterverwendbar","Nachrüsten","Austausch"))) | BJ15: =IF($A15="","",_xlfn.TEXTJOIN(", ",TRUE(),IF(AI15<>"",AI$3,""),IF(AJ15<>"",AJ$3,""),IF(AK15<>"",AK$3,""),IF(AL15<>"",AL$3,""),IF(AM15<>"",AM$3,""),IF(AN15<>"",AN$3,""),IF(AO15<>"",AO$3,""),IF(AP15<>"",AP$3,""),IF(AQ15<>"",AQ$3,""),IF(AR15<>"",AR$3,""),IF(AS15<>"",AS$3,""),IF(AT15<>"",AT$3,""),IF(AU15<>"",AU$3,""),IF(AV15<>"",AV$3,""),IF(AW15<>"",AW$3,""),IF(AX15<>"",AX$3,""),IF(AY15<>"",AY$3,""),IF(AZ15<>"",AZ$3,""),IF(BA15<>"",BA$3,""),IF(BB15<>"",BB$3,""),IF(BC15<>"",BC$3,""),IF(BD15<>"",BD$3,""),IF(BE15<>"",BE$3,""),IF(BF15<>"",BF$3,""),IF(BG15<>"",BG$3,""),IF(BH15<>"",BH$3,""))) | BK15: =IF(OR($A15="",$AE15=""),"",IF(BI15=$AE15,"Ja","Nein")) | BL15: =IF($A15="","",IF(NOT(ISNUMBER(SEARCH("westnetz",$D15))),"–",IF($I15="Ja",IF($K15="Modul 2","MK 8 (Kaskade: Z1 SteuVE, Z2 Haushalt)","MK 2 (Überschuss)"),IF($K15="Modul 2","MK 0 + eigener Zählpunkt SteuVE","MK 0"))))
AG16: =IF($A16="","",COUNTIF($E16:$I16,"Ja")) | AH16: =IF($A16="","",IF(AND(COUNTIF($E16:$H16,"Ja")>0,N($J16)>=4.2),"Ja","Nein")) | AI16: =IF($A16="","",IF(AND(OR($L16="DIN 43853 Zählertafel ohne Schutzklasse II",$L16="DIN 43853 Norm-Zählertafel (Schutzklasse II)",$L16="DIN 43870 Norm-Zählertafel mit Vorsicherung"),$AG16>0),Regeln!$E$5,"")) | AJ16: =IF($A16="","",IF(AND(OR($L16="DIN 43870 Zählerschrank, Trennvorrichtung im AAR",$L16="DIN 43870 Zählerschrank, NH-Sicherung im NAR"),OR($AA16="unter 10 mm² oder starr",$AA16="Unbekannt",$AA16=""),$AG16>0),Regeln!$E$6,"")) | AK16: =IF($A16="","",IF(AND($V16="Nein",$AG16>0),Regeln!$E$7,"")) | AL16: =IF($A16="","",IF(AND(OR($AH16="Ja",$I16="Ja"),$O16="Nein"),Regeln!$E$8,"")) | AM16: =IF($A16="","",IF(AND($K16="Modul 2",N($N16)<1),Regeln!$E$9,"")) | AN16: =IF($A16="","",IF(AND($P16="Nein",$AG16>0,OR(ISNUMBER(SEARCH("westnetz",$D16)),$M16="3-Punkt")),Regeln!$E$10,"")) | AO16: =IF($A16="","",IF(AND($Q16="Nein",$AG16>0),Regeln!$E$11,"")) | AP16: =IF($A16="","",IF(AND($R16="1-phasig",OR(N($J16)>4.6,$I16="Ja")),Regeln!$E$12,"")) | AQ16: =IF($A16="","",IF(OR($U16="Nein",$U16="Unbekannt"),Regeln!$E$13,"")) | AR16: =IF($A16="","",IF(OR($S16="TN-C",$S16="Unbekannt"),Regeln!$E$14,"")) | AS16: =IF($A16="","",IF(AND(N($T16)>0,N($T16)<50,$AG16>=2),Regeln!$E$15,"")) | AT16: =IF($A16="","",IF(AND($E16="Ja",N($J16)>12),Regeln!$E$16,"")) | AU16: =IF($A16="","",IF($L16="Unbekannt",Regeln!$E$17,"")) | AV16: =IF($A16="","",IF(AND(OR($L16="DIN 43870 Zählerschrank, Trennvorrichtung im AAR",$L16="DIN 43870 Zählerschrank, NH-Sicherung im NAR"),$AG16>0),Regeln!$E$18,"")) | AW16: =IF($A16="","",IF(AND(ISNUMBER(SEARCH("westnetz",$D16)),OR($AH16="Ja",$I16="Ja"),$X16="Nein"),Regeln!$E$19,"")) | AX16: =IF($A16="","",IF(AND(ISNUMBER(SEARCH("westnetz",$D16)),OR($W16="Relais (potentialfrei)",$W16="Digital + Relais",AND($I16="Ja",N($AC16)>=25)),$Y16="Nein"),Regeln!$E$20,"")) | AY16: =IF($A16="","",IF(AND(ISNUMBER(SEARCH("westnetz",$D16)),OR($W16="Digital (RJ45 / EEBUS)",$W16="Digital + Relais"),$Z16="Nein"),Regeln!$E$21,"")) | AZ16: =IF($A16="","",IF(AND(ISNUMBER(SEARCH("westnetz",$D16)),N($AB16)>30),Regeln!$E$22,"")) | BA16: =IF($A16="","",IF(AND($AA16="10 mm² flexibel",N($AB16)*1000/(SQRT(3)*400)>32),Regeln!$E$23,"")) | BB16: =IF($A16="","",IF(AND(ISNUMBER(SEARCH("westnetz",$D16)),$I16="Ja",N($AC16)>=25),Regeln!$E$24,"")) | BC16: =IF($A16="","",IF(AND(ISNUMBER(SEARCH("westnetz",$D16)),$I16="Ja",OR($AH16="Ja",N($AC16)>7)),Regeln!$E$25,"")) | BD16: =IF($A16="","",IF(AND(ISNUMBER(SEARCH("westnetz",$D16)),$AH16="Ja"),Regeln!$E$26,"")) | BE16: =IF($A16="","",IF(AND(ISNUMBER(SEARCH("westnetz",$D16)),OR($W16="Relais (potentialfrei)",$W16="Digital + Relais"),$M16="3-Punkt",$AD16="Nein"),Regeln!$E$27,"")) | BF16: =IF($A16="","",IF(AND(ISNUMBER(SEARCH("westnetz",$D16)),$I16="Ja"),Regeln!$E$28,"")) | BG16: =IF($A16="","",IF(AND(ISNUMBER(SEARCH("westnetz",$D16)),$H16="Ja"),Regeln!$E$29,"")) | BH16: =IF($A16="","",IF(AND(ISNUMBER(SEARCH("westnetz",$D16)),OR($W16="Relais (potentialfrei)",$W16="Digital + Relais")),Regeln!$E$30,"")) | BI16: =IF($A16="","",IF($AG16=0,"Kein Vorhaben",CHOOSE(MAX(AI16:BH16)+1,"Weiterverwendbar","Nachrüsten","Austausch"))) | BJ16: =IF($A16="","",_xlfn.TEXTJOIN(", ",TRUE(),IF(AI16<>"",AI$3,""),IF(AJ16<>"",AJ$3,""),IF(AK16<>"",AK$3,""),IF(AL16<>"",AL$3,""),IF(AM16<>"",AM$3,""),IF(AN16<>"",AN$3,""),IF(AO16<>"",AO$3,""),IF(AP16<>"",AP$3,""),IF(AQ16<>"",AQ$3,""),IF(AR16<>"",AR$3,""),IF(AS16<>"",AS$3,""),IF(AT16<>"",AT$3,""),IF(AU16<>"",AU$3,""),IF(AV16<>"",AV$3,""),IF(AW16<>"",AW$3,""),IF(AX16<>"",AX$3,""),IF(AY16<>"",AY$3,""),IF(AZ16<>"",AZ$3,""),IF(BA16<>"",BA$3,""),IF(BB16<>"",BB$3,""),IF(BC16<>"",BC$3,""),IF(BD16<>"",BD$3,""),IF(BE16<>"",BE$3,""),IF(BF16<>"",BF$3,""),IF(BG16<>"",BG$3,""),IF(BH16<>"",BH$3,""))) | BK16: =IF(OR($A16="",$AE16=""),"",IF(BI16=$AE16,"Ja","Nein")) | BL16: =IF($A16="","",IF(NOT(ISNUMBER(SEARCH("westnetz",$D16))),"–",IF($I16="Ja",IF($K16="Modul 2","MK 8 (Kaskade: Z1 SteuVE, Z2 Haushalt)","MK 2 (Überschuss)"),IF($K16="Modul 2","MK 0 + eigener Zählpunkt SteuVE","MK 0"))))
